<?xml version="1.0" ?>
<robot name="rosbot" xmlns:xacro="http://www.ros.org/wiki/xacro">

<material name="silver">
  <color rgba="0.700 0.700 0.700 1.000"/>
</material>

<xacro:property name="body_color" value="Gazebo/Silver" />

<gazebo reference="base_link">
  <material>${body_color}</material>
  <mu1>0.2</mu1>
  <mu2>0.2</mu2>
  <self_collide>true</self_collide>
  <gravity>true</gravity>
</gazebo>

<gazebo reference="right_wheel_1">
  <material>${body_color}</material>
  <mu1>0.2</mu1>
  <mu2>0.2</mu2>
  <self_collide>true</self_collide>
</gazebo>

<gazebo reference="left_wheel_1">
  <material>${body_color}</material>
  <mu1>0.2</mu1>
  <mu2>0.2</mu2>
  <self_collide>true</self_collide>
</gazebo>

<gazebo reference="lidar_1">
  <material>${body_color}</material>
  <mu1>0.2</mu1>
  <mu2>0.2</mu2>
  <self_collide>true</self_collide>
</gazebo>


  <gazebo>  

        <plugin filename="gz-sim-sensors-system" name="gz::sim::systems::Sensors">
            <render_engine>ogre2</render_engine>
        </plugin>


        <plugin filename="gz-sim-joint-state-publisher-system" name="gz::sim::systems::JointStatePublisher">
        <topic>/joint_states</topic>      
        </plugin>


      <plugin
        filename="gz-sim-diff-drive-system"
        name="gz::sim::systems::DiffDrive">
        <left_joint>left_wheel_joint</left_joint>
        <right_joint>right_wheel_joint</right_joint>
        <wheel_separation>0.2</wheel_separation>
        <wheel_radius>0.05</wheel_radius>
        <odom_publish_frequency>30</odom_publish_frequency>
        <topic>/cmd_vel</topic>  
        <tf_topic>/tf</tf_topic>        
        <frame_id>odom</frame_id>     
        <odom_topic>odom</odom_topic>             
        <child_frame_id>base_footprint</child_frame_id>            

</plugin>
</gazebo>

<gazebo reference="lidar_1">
        <sensor name='gpu_lidar' type='gpu_lidar'>
          <pose>0 0 0 0 0 0</pose>
          <topic>scan</topic>
          <gz_frame_id>lidar_1</gz_frame_id>          
          <update_rate>10</update_rate>
          <lidar>
            <scan>
              <horizontal>
                <samples>640</samples>
                <resolution>1</resolution>
                <min_angle>0</min_angle>
                <max_angle>6.280000</max_angle>
              </horizontal>
              <vertical>
                <samples>1</samples>
                <resolution>1</resolution>
                <min_angle>0.0</min_angle>
                <max_angle>0.0</max_angle>
              </vertical>
            </scan>
            <range>
              <min>0.08</min>
              <max>10.0</max>
              <resolution>0.01</resolution>
            </range>
          </lidar>
          <visualize>true</visualize>
        </sensor>
 </gazebo>

<link name="base_footprint"/>


<link name="base_link">
  <inertial>
    <origin xyz="0.004279734419382094 0.0 0.05375741183973183" rpy="0 0 0"/>
    <mass value="2.34056579648116"/>
    <inertia ixx="0.008048" iyy="0.008642" izz="0.014848" ixy="-0.0" iyz="0.0" ixz="-0.000438"/>
  </inertial>
  <visual>
    <origin xyz="0 0 0" rpy="0 0 0"/>
    <geometry>
      <mesh filename="file://$(find rosbot_description)/meshes/base_link.stl" scale="0.001 0.001 0.001"/>
    </geometry>
    <material name="silver"/>
  </visual>
  <collision>
    <origin xyz="0 0 0" rpy="0 0 0"/>
    <geometry>
      <mesh filename="file://$(find rosbot_description)/meshes/base_link.stl" scale="0.001 0.001 0.001"/>
    </geometry>
  </collision>
</link>

<link name="right_wheel_1">
  <inertial>
    <origin xyz="-5.790023100122029e-18 -0.012499999999999997 3.7252903539730653e-10" rpy="0 0 0"/>
    <mass value="0.1826050729899067"/>
    <inertia ixx="0.000124" iyy="0.000228" izz="0.000124" ixy="-0.0" iyz="-0.0" ixz="0.0"/>
  </inertial>
  <visual>
    <origin xyz="-0.0 0.1 -0.05" rpy="0 0 0"/>
    <geometry>
      <mesh filename="file://$(find rosbot_description)/meshes/right_wheel_1.stl" scale="0.001 0.001 0.001"/>
    </geometry>
    <material name="silver"/>
  </visual>
  <collision>
    <origin xyz="-0.0 0.1 -0.05" rpy="0 0 0"/>
    <geometry>
      <mesh filename="file://$(find rosbot_description)/meshes/right_wheel_1.stl" scale="0.001 0.001 0.001"/>
    </geometry>
  </collision>
</link>

<link name="left_wheel_1">
  <inertial>
    <origin xyz="1.737006930036608e-17 0.012499999999999997 3.725290284584126e-10" rpy="0 0 0"/>
    <mass value="0.18260507298990675"/>
    <inertia ixx="0.000124" iyy="0.000228" izz="0.000124" ixy="-0.0" iyz="0.0" ixz="0.0"/>
  </inertial>
  <visual>
    <origin xyz="-0.0 -0.1 -0.05" rpy="0 0 0"/>
    <geometry>
      <mesh filename="file://$(find rosbot_description)/meshes/left_wheel_1.stl" scale="0.001 0.001 0.001"/>
    </geometry>
    <material name="silver"/>
  </visual>
  <collision>
    <origin xyz="-0.0 -0.1 -0.05" rpy="0 0 0"/>
    <geometry>
      <mesh filename="file://$(find rosbot_description)/meshes/left_wheel_1.stl" scale="0.001 0.001 0.001"/>
    </geometry>
  </collision>
</link>

<link name="lidar_1">
  <inertial>
    <origin xyz="0.0 0.0 0.010000000000000009" rpy="0 0 0"/>
    <mass value="0.0754575997873079"/>
    <inertia ixx="1.9e-05" iyy="1.9e-05" izz="3.3e-05" ixy="0.0" iyz="0.0" ixz="0.0"/>
  </inertial>
  <visual>
    <origin xyz="-0.05 -0.0 -0.21" rpy="0 0 0"/>
    <geometry>
      <mesh filename="file://$(find rosbot_description)/meshes/lidar_1.stl" scale="0.001 0.001 0.001"/>
    </geometry>
    <material name="silver"/>
  </visual>
  <collision>
    <origin xyz="-0.05 -0.0 -0.21" rpy="0 0 0"/>
    <geometry>
      <mesh filename="file://$(find rosbot_description)/meshes/lidar_1.stl" scale="0.001 0.001 0.001"/>
    </geometry>
  </collision>
</link>

<joint name="base_joint" type="fixed">
  <origin xyz="0.0 0.0 0.0" rpy="0 0 0"/>
  <parent link="base_footprint"/>
  <child link="base_link"/>
</joint>


<joint name="right_wheel_joint" type="continuous">
  <origin xyz="0.0 -0.1 0.05" rpy="0 0 0"/>
  <parent link="base_link"/>
  <child link="right_wheel_1"/>
  <axis xyz="0.0 1.0 0.0"/>
</joint>

<joint name="left_wheel_joint" type="continuous">
  <origin xyz="0.0 0.1 0.05" rpy="0 0 0"/>
  <parent link="base_link"/>
  <child link="left_wheel_1"/>
  <axis xyz="0.0 1.0 0.0"/>
</joint>

<joint name="lidar_joint" type="fixed">
  <origin xyz="0.05 0.0 0.21" rpy="0 0 0"/>
  <parent link="base_link"/>
  <child link="lidar_1"/>
</joint>


</robot>
